Workbook

Sheet Students
A1: University ID | B1: Last Name | C1: First Name | D1: Prog Code | E1: Subject Name | F1: Fees | G1: Class | H1: FT/PT | I1: Residence Hall
A2: 9100 | B2: Kawamoto | C2: Motonari | D2: BL-BI | E2: Biology | F2: =VLOOKUP(E2,'Program Fees'!A2:B24,2,FALSE) -> 27 | G2: Senior | H2: Full time | I2: Newton
A3: 9101 | B3: Niwa | C3: Romi | D3: BL-GEOL | E3: Geology | F3: =VLOOKUP(E3,'Program Fees'!A3:B25,2,FALSE) -> 36 | G3: Senior | H3: Full time | I3: King
A4: 9102 | B4: Echevarría Agosto | C4: Raffi | D4: BL-BUS | E4: Business | F4: =VLOOKUP(E4,'Program Fees'!A4:B26,2,FALSE) -> 86 | G4: Sophomore | H4: Part time | I4: Abernathy
A5: 9103 | B5: Cruz Alanis | C5: Jasper | D5: BL-MUS | E5: Music | F5: =VLOOKUP(E5,'Program Fees'!A5:B27,2,FALSE) -> 46 | G5: Masters | H5: Full time | I5: Abernathy
A6: 9104 | B6: Martinez | C6: Mary | D6: BL-EDUC | E6: Education | F6: =VLOOKUP(E6,'Program Fees'!A6:B28,2,FALSE) -> 74 | G6: Doctorate | H6: Full time | I6: Seale
A7: 9105 | B7: Cotto Alfaro | C7: Bernabé | D7: BL-JOUR | E7: Journalism | F7: =VLOOKUP(E7,'Program Fees'!A7:B29,2,FALSE) -> 81 | G7: Senior | H7: Full time | I7: Carmichael
A8: 9106 | B8: Valles Amador | C8: Jeny | D8: BL-OPT | E8: Optometry | F8: =VLOOKUP(E8,'Program Fees'!A8:B30,2,FALSE) -> 75 | G8: Professional Fourth | H8: Full time | I8: off-campus
A9: 9107 | B9: Rainey | C9: David | D9: BL-BUS | E9: Business | F9: =VLOOKUP(E9,'Program Fees'!A2:B24,2,) -> 86 | G9: Senior | H9: Part time | I9: Seale
A10: 9108 | B10: Barraza Anguiano | C10: Lorujama | D10: BL-UDIV | E10: Theatre | F10: =VLOOKUP(E10,'Program Fees'!A10:B32,2,FALSE) -> 64 | G10: Sophomore | H10: Full time | I10: off-campus
A11: 9109 | B11: Nemoto | C11: Haruna | D11: BL-EDUC | E11: Education | F11: =VLOOKUP(E11,'Program Fees'!A2:B24,2,FALSE) -> 74 | G11: Junior | H11: Full time | I11: Jackson
A12: 9110 | B12: Abe | C12: Osami | D12: BL-AMID | E12: Theatre | F12: =VLOOKUP(E12,'Program Fees'!A2:B24,2,FALSE) -> 64 | G12: Senior | H12: Full time | I12: Seale
A13: 9111 | B13: Lozano Aranda | C13: Amilcar | D13: BL-EALC | E13: Education | F13: =VLOOKUP(E13,'Program Fees'!A2:B24,2,FALSE) -> 74 | G13: Junior | H13: Part time | I13: Evers
A14: 9112 | B14: Alva Arce | C14: Romelio | D14: BL-EDUC | E14: Education | F14: =VLOOKUP(E14,'Program Fees'!A2:B24,2,FALSE) -> 74 | G14: Senior | H14: Full time | I14: Seale
A15: 9113 | B15: Muñoz Arce | C15: Aurea | D15: BL-HPER | E15: Health | F15: =VLOOKUP(E15,'Program Fees'!A2:B24,2,FALSE) -> 58 | G15: Sophomore | H15: Full time | I15: Newton
A16: 9114 | B16: Hernández Arteaga | C16: Zuleica | D16: BL-FINA | E16: Fine Arts | F16: =VLOOKUP(E16,'Program Fees'!A3:B25,2,FALSE) -> 49 | G16: Junior | H16: Full time | I16: off-campus
A17: 9115 | B17: Woosley | C17: Rebecca | D17: BL-BI | E17: Health | F17: =VLOOKUP(E17,'Program Fees'!A4:B26,2,FALSE) -> 58 | G17: Sophomore | H17: Full time | I17: Evers
A18: 9116 | B18: Asai | C18: Kiyotaka | D18: BL-JOUR | E18: Journalism | F18: =VLOOKUP(E18,'Program Fees'!A5:B27,2,FALSE) -> 81 | G18: Junior | H18: Full time | I18: Evers
A19: 9117 | B19: Takaki | C19: Rieka | D19: BL-EDUC | E19: Education | F19: =VLOOKUP(E19,'Program Fees'!A6:B28,2,FALSE) -> 74 | G19: Junior | H19: Full time | I19: Carmichael
A20: 9118 | B20: Vicente | C20: David | D20: BL-MUS | E20: Music | F20: =VLOOKUP(E20,'Program Fees'!A7:B29,2,FALSE) -> 46 | G20: Junior | H20: Full time | I20: Jackson
A21: 9119 | B21: Cordova Avilés | C21: Nasha | D21: BL-CJUS | E21: Criminal Justice | F21: =VLOOKUP(E21,'Program Fees'!A2:B24,2,FALSE) -> 60 | G21: Junior | H21: Full time | I21: King
A22: 9120 | B22: Shaw | C22: Richard | D22: BL-BI | E22: Biology | F22: =VLOOKUP(E22,'Program Fees'!A2:B24,2,FALSE) -> 27 | G22: Junior | H22: Full time | I22: off-campus
A23: 9121 | B23: Tyler | C23: Ella | D23: BL-BUS | E23: Business | F23: =VLOOKUP(E23,'Program Fees'!A2:B24,2,FALSE) -> 86 | G23: Sophomore | H23: Full time | I23: Carmichael
A24: 9122 | B24: Riddick | C24: Robert | D24: BL-INFO | E24: Informatics | F24: =VLOOKUP(E24,'Program Fees'!A11:B33,2,FALSE) -> 85 | G24: Junior | H24: Part time | I24: Evers
A25: 9123 | B25: Hurtado Barela | C25: Dunstano | D25: BL-PSY | E25: Psychology | F25: =VLOOKUP(E25,'Program Fees'!A12:B34,2,FALSE) -> 24 | G25: Senior | H25: Full time | I25: Abernathy
A26: 9124 | B26: Wester | C26: Lisa | D26: BL-BUS | E26: Business | F26: =VLOOKUP(E26,'Program Fees'!A2:B24,2,FALSE) -> 86 | G26: Junior | H26: Full time | I26: Seale
A27: 9125 | B27: Hardin | C27: Lucien | D27: BL-PSY | E27: Psychology | F27: =VLOOKUP(E27,'Program Fees'!A2:B24,2,FALSE) -> 24 | G27: Senior | H27: Full time | I27: King
A28: 9126 | B28: Chang | C28: Jacob | D28: BL-FINA | E28: Fine Arts | F28: =VLOOKUP(E28,'Program Fees'!A2:B24,2,FALSE) -> 49 | G28: Senior | H28: Part time | I28: Seale
A29: 9127 | B29: Cervántez Benavidez | C29: Jovianne | D29: BL-EDUC | E29: Education | F29: =VLOOKUP(E29,'Program Fees'!A2:B24,2,FALSE) -> 74 | G29: Senior | H29: Full time | I29: King
A30: 9128 | B30: Connors | C30: April | D30: BL-SCS | E30: Music | F30: =VLOOKUP(E30,'Program Fees'!A2:B24,2,FALSE) -> 46 | G30: Undergrad Special | H30: Part time | I30: Newton
A31: 9129 | B31: Vasquez | C31: Geraldine | D31: BL-BUS | E31: Business | F31: =VLOOKUP(E31,'Program Fees'!A2:B24,2,FALSE) -> 86 | G31: Sophomore | H31: Full time | I31: Seale
A32: 9130 | B32: Lucas | C32: Julio | D32: BL-BUS | E32: Business | F32: =VLOOKUP(E32,'Program Fees'!A2:B24,2,FALSE) -> 86 | G32: Senior | H32: Full time | I32: Seale
A33: 9131 | B33: Hughes | C33: Peter | D33: BL-TELC | E33: Telecommunications | F33: =VLOOKUP(E33,'Program Fees'!A2:B24,2,FALSE) -> 41 | G33: Senior | H33: Full time | I33: off-campus
A34: 9132 | B34: Rosales | C34: Helen | D34: BL-HPER | E34: Health | F34: =VLOOKUP(E34,'Program Fees'!A2:B24,2,FALSE) -> 58 | G34: Sophomore | H34: Full time | I34: Evers
A35: 9133 | B35: Monnin | C35: Carl | D35: BL-FINA | E35: Fine Arts | F35: =VLOOKUP(E35,'Program Fees'!A2:B24,2,FALSE) -> 49 | G35: Sophomore | H35: Full time | I35: Carmichael
A36: 9134 | B36: Peachey | C36: Byron | D36: BL-BI | E36: Biology | F36: =VLOOKUP(E36,'Program Fees'!A2:B24,2,FALSE) -> 27 | G36: Junior | H36: Part time | I36: Jackson
A37: 9135 | B37: Henderson | C37: Lydia | D37: BL-BUS | E37: Business | F37: =VLOOKUP(E37,'Program Fees'!A2:B24,2,FALSE) -> 86 | G37: Masters | H37: Full time | I37: off-campus
A38: 9136 | B38: Fernandez | C38: Arthur | D38: BL-BUS | E38: Business | F38: =VLOOKUP(E38,'Program Fees'!A2:B24,2,FALSE) -> 86 | G38: Masters | H38: Full time | I38: Carmichael
A39: 9137 | B39: Newman | C39: Bradley | D39: BL-AMID | E39: Apparel Merchandising | F39: =VLOOKUP(E39,'Program Fees'!A2:B24,2,FALSE) -> 25 | G39: Sophomore | H39: Full time | I39: King
A40: 9138 | B40: Fuller | C40: Jason | D40: BL-BUS | E40: Business | F40: =VLOOKUP(E40,'Program Fees'!A2:B24,2,FALSE) -> 86 | G40: Senior | H40: Full time | I40: Carmichael
...

Sheet Program Fees
A1: Program | B1: Fee
A2: Anthropology | B2: 23
A3: Apparel Merchandising | B3: 25
A4: Biology | B4: 27
A5: Business | B5: 86
A6: Communication | B6: 21
A7: Criminal Justice | B7: 60
A8: East Asian Language and Culture | B8: 58
A9: Education | B9: 74
A10: English | B10: 26
A11: Fine Arts | B11: 49
A12: Geology | B12: 36
A13: Health | B13: 58
... A24: Theatre | B24: 64
